I'm sorry, but an uncaught exception occurred.

While running game code:
  File "game/script.rpy", line 15, in script call
    call neg1 from _call_neg1
  File "game/script.rpy", line 15, in script call
    call neg1 from _call_neg1
  File "game/siA.rpy", line 2029, in script
    $ rtrn()
  File "game/siA.rpy", line 2029, in <module>
    $ rtrn()
  File "game/01DD.rpy", line 28, in rtrn
    if aoeusnth is True:
UnboundLocalError: local variable 'aoeusnth' referenced before assignment

-- Full Traceback ------------------------------------------------------------

Full traceback:
  File "game/script.rpy", line 15, in script call
    call neg1 from _call_neg1
  File "game/script.rpy", line 15, in script call
    call neg1 from _call_neg1
  File "game/siA.rpy", line 2029, in script
    $ rtrn()
  File "C:\Users\student\Desktop\Applications\renpy-8.0.1-sdk\renpy\ast.py", line 1131, in execute
    renpy.python.py_exec_bytecode(self.code.bytecode, self.hide, store=self.store)
  File "C:\Users\student\Desktop\Applications\renpy-8.0.1-sdk\renpy\python.py", line 1061, in py_exec_bytecode
    exec(bytecode, globals, locals)
  File "game/siA.rpy", line 2029, in <module>
    $ rtrn()
  File "game/01DD.rpy", line 28, in rtrn
    if aoeusnth is True:
UnboundLocalError: local variable 'aoeusnth' referenced before assignment

Windows-10-10.0.19044 AMD64
Ren'Py 8.0.3.22090809
AAA 0.0.3.2666
Thu Dec 22 16:48:05 2022
